Workbook

Sheet Dashboard
B2: Sales Performance Dashboard
B3: Jan 2024 – Dec 2025 | Customer Concentration • Discount & Margin Erosion • Regional Performance
B5: TOTAL REVENUE | E5: TOTAL NET PROFIT | H5: OVERALL MARGIN % | K5: TOP 10 CUSTOMERS' REV. SHARE | N5: DISCOUNT RATE INCREASE (24 MO) | Q5: SOUTH RETURN RATE vs. CO. AVG
B6: =Analysis_Data!B2 -> 1945626.1 | E6: =Analysis_Data!B3 -> 744281.38 | H6: =Analysis_Data!B4 -> 0.38254081 | K6: =Analysis_Data!G20 -> 0.33590926 | N6: =Analysis_Data!E59-Analysis_Data!E36 -> 0.15398747 | Q6: =Analysis_Data!E96-Analysis_Data!B6 -> 0.13646656
K8: Revenue concentration risk | N8: Margin pressure from discounting | Q8: vs. company-wide return rate
B10: Customer Revenue Concentration | K10: Discount Creep & Margin Erosion
B31: Regional Revenue Trend (South in Decline) | K31: Revenue vs. Return Rate by Region

Sheet Insights_Recommendations
B2: Insights & Recommendations
B4: Analysis based on 4,410 transactions, Jan 2024 – Dec 2025. All figures reference the live formulas in Analysis_Data and Sales_Transactions, so they update automatically if the underlying data changes.
B6: 1. Customer Revenue Concentration Risk
B7: Finding
B8: • The top 10 customers (5.6% of the 180-customer base) generate roughly 34% of total revenue, and the top 18 customers (10%) generate roughly 45%. Five of the top six accounts are tagged ‘Key Account,’ meaning a large share of revenue rests on a small number of relationships.
B9: • See the Pareto chart on the Dashboard — cumulative revenue share climbs steeply across the first 10–20 customers before flattening, the classic signature of concentration risk.
B10: Business Impact
B11: • Losing even one or two top accounts could meaningfully dent total revenue and profit with little warning, since the long tail of 160+ smaller customers cannot quickly absorb that gap.
B12: Recommended Actions
B13: • Set up an account health program (usage trend, satisfaction, renewal/reorder cadence) for the top 20 customers.
B14: • Assign named account owners and proactive check-ins for all ‘Key Account’-segment customers.
B15: • Invest in mid-tier (‘Standard’ segment) customer growth to diversify revenue away from the top 10.
... B37: • Set a target to bring South's return rate toward the ~5–6% company baseline, then track its revenue trend for recovery.

Sheet Overview
B2: Sales Transactions Dataset — Practice Case Study
B4: This workbook contains 2 years (Jan 2024 – Dec 2025) of order-level sales transactions for a multi-category retail business operating across 5 regions and 3 sales channels. The data is intentionally asymmetric — it reflects the kind of skewed, imperfect patterns found in real business datasets rather than a clean, evenly distributed sample.
B6: Dataset at a Glance
B7: • Rows (transactions): 4,410
B8: • Date range: 2024-01-01 to 2025-12-31
B9: • Regions: Central, East, North, South, West
B10: • Sales channels: Online, Retail, Wholesale
B11: • Product categories: Apparel, Electronics, Home & Kitchen, Office Supplies, Sporting Goods
B12: • Unique customers: 180
B14: Three Business Problems to Investigate
B15: The data has been generated so that each of the following issues is genuinely present and discoverable through analysis (pivot tables, charts, or formulas) — none of them are pre-solved in this workbook.
B17: 1. Customer Revenue Concentration Risk
... B29: • Quantity, pricing, and discount patterns vary by channel and category, as in real retail data.

Sheet Data_Dictionary
A1: Column | B1: Type | C1: Description
A2: Order_ID | B2: Text | C2: Unique order identifier (a few intentional duplicates present)
A3: Order_Date | B3: Date | C3: Date the order was placed
A4: Year | B4: Formula | C4: Year extracted from Order_Date
A5: Quarter | B5: Formula | C5: Calendar quarter extracted from Order_Date (Q1–Q4)
A6: Region | B6: Text | C6: Sales region: North, South, East, West, Central
A7: Sales_Channel | B7: Text | C7: Online, Retail, or Wholesale
A8: Sales_Rep | B8: Text | C8: Sales representative assigned to the order
A9: Customer_ID | B9: Text | C9: Unique customer identifier
A10: Customer_Name | B10: Text | C10: Customer name
A11: Customer_Segment | B11: Text | C11: Key Account / Standard / New & Occasional, based on historical order volume
A12: Product_Category | B12: Text | C12: Electronics, Home & Kitchen, Apparel, Sporting Goods, Office Supplies
... A24: Payment_Method | B24: Text | C24: Credit Card, Bank Transfer, PayPal, or Cash on Delivery

Sheet Sales_Transactions
A1: Order_ID | B1: Order_Date | C1: Year | D1: Quarter | E1: Region | F1: Sales_Channel | G1: Sales_Rep | H1: Customer_ID | I1: Customer_Name | J1: Customer_Segment | K1: Product_Category | L1: Product_Name | M1: Unit_Price | N1: Quantity | O1: Discount_Pct | P1: Unit_Cost | Q1: Revenue | R1: Discount_Amount | S1: COGS | T1: Net_Profit | U1: Margin_Pct | V1: Return_Flag | W1: Payment_Method
A2: ORD-00001 | B2: 45292 | C2: =YEAR(B2) -> 2024 | D2: ="Q"&ROUNDUP(MONTH(B2)/3,0) -> Q1 | E2: West | F2: Online | G2: Nourhan Aly | H2: CUST-0006 | I2: Mona Ibrahim | J2: Key Account | K2: Sporting Goods | L2: Resistance Bands | M2: 124.31 | N2: 3 | O2: 0.0657 | P2: 59.83 | Q2: =M2*N2*(1-O2) -> 348.4285 | R2: =M2*N2*O2 -> 24.501501 | S2: =P2*N2 -> 179.49 | T2: =Q2-S2 -> 168.9385 | U2: =IFERROR(T2/Q2,0) -> 0.48485844 | V2: No | W2: Credit Card
A3: ORD-00002 | B3: 45292 | C3: =YEAR(B3) -> 2024 | D3: ="Q"&ROUNDUP(MONTH(B3)/3,0) -> Q1 | E3: North | F3: Retail | G3: Tarek Aboul | H3: CUST-0016 | I3: Karim El-Masry | J3: Standard | K3: Home & Kitchen | L3: Vacuum Cleaner | M3: 84.75 | N3: 5 | O3: 0.0286 | P3: 44.15 | Q3: =M3*N3*(1-O3) -> 411.63075 | R3: =M3*N3*O3 -> 12.11925 | S3: =P3*N3 -> 220.75 | T3: =Q3-S3 -> 190.88075 | U3: =IFERROR(T3/Q3,0) -> 0.46371839 | V3: No | W3: Cash on Delivery
A4: ORD-00003 | B4: 45293 | C4: =YEAR(B4) -> 2024 | D4: ="Q"&ROUNDUP(MONTH(B4)/3,0) -> Q1 | E4: East | F4: Online | G4: Omar Said | H4: CUST-0137 | I4: Wael El-Sayed | J4: New / Occasional | K4: Electronics | L4: Noise-Cancel Headphones | M4: 296.74 | N4: 4 | O4: 0.1413 | P4: 196.46 | Q4: =M4*N4*(1-O4) -> 1019.2426 | R4: =M4*N4*O4 -> 167.71745 | S4: =P4*N4 -> 785.84 | T4: =Q4-S4 -> 233.40255 | U4: =IFERROR(T4/Q4,0) -> 0.22899608 | V4: No | W4: Cash on Delivery
A5: ORD-00004 | B5: 45293 | C5: =YEAR(B5) -> 2024 | D5: ="Q"&ROUNDUP(MONTH(B5)/3,0) -> Q1 | E5: East | F5: Online | G5: Yara Mostafa | H5: CUST-0008 | I5: Nour Ibrahim | J5: Key Account | K5: Office Supplies | L5: Desk Organizer | M5: 112.4 | N5: 1 | O5: 0.1513 | P5: 58.22 | Q5: =M5*N5*(1-O5) -> 95.39388 | R5: =M5*N5*O5 -> 17.00612 | S5: =P5*N5 -> 58.22 | T5: =Q5-S5 -> 37.17388 | U5: =IFERROR(T5/Q5,0) -> 0.38968831 | V5: No | W5: Credit Card
A6: ORD-00005 | B6: 45293 | C6: =YEAR(B6) -> 2024 | D6: ="Q"&ROUNDUP(MONTH(B6)/3,0) -> Q1 | E6: North | F6: Retail | G6: Mona Hassan | H6: CUST-0037 | I6: Mariam Aziz | J6: Standard | K6: Sporting Goods | L6: Bicycle Helmet | M6: 131.06 | N6: 2 | O6: 0.1 | P6: 62.45 | Q6: =M6*N6*(1-O6) -> 235.908 | R6: =M6*N6*O6 -> 26.212 | S6: =P6*N6 -> 124.9 | T6: =Q6-S6 -> 111.008 | U6: =IFERROR(T6/Q6,0) -> 0.47055632 | V6: No | W6: PayPal
A7: ORD-00006 | B7: 45293 | C7: =YEAR(B7) -> 2024 | D7: ="Q"&ROUNDUP(MONTH(B7)/3,0) -> Q1 | E7: South | F7: Wholesale | G7: Khaled Fathy | H7: CUST-0155 | I7: Reem Rashed | J7: New / Occasional | K7: Office Supplies | L7: Desk Organizer | M7: 207.78 | N7: 5 | O7: 0 | P7: 85.26 | Q7: =M7*N7*(1-O7) -> 1038.9 | R7: =M7*N7*O7 -> 0 | S7: =P7*N7 -> 426.3 | T7: =Q7-S7 -> 612.6 | U7: =IFERROR(T7/Q7,0) -> 0.58966214 | V7: No | W7: Cash on Delivery
A8: ORD-00007 | B8: 45293 | C8: =YEAR(B8) -> 2024 | D8: ="Q"&ROUNDUP(MONTH(B8)/3,0) -> Q1 | E8: South | F8: Retail | G8: Sara Adel | H8: CUST-0008 | I8: Nour Ibrahim | J8: Key Account | K8: Apparel | L8: Cotton T-Shirt Pack | M8: 96.73 | N8: 1 | O8: 0 | P8: 40.9 | Q8: =M8*N8*(1-O8) -> 96.73 | R8: =M8*N8*O8 -> 0 | S8: =P8*N8 -> 40.9 | T8: =Q8-S8 -> 55.83 | U8: =IFERROR(T8/Q8,0) -> 0.57717358 | V8: No | W8: PayPal
A9: ORD-00008 | B9: 45294 | C9: =YEAR(B9) -> 2024 | D9: ="Q"&ROUNDUP(MONTH(B9)/3,0) -> Q1 | E9: South | F9: Online | G9: Khaled Fathy | H9: CUST-0009 | I9: Reem Naguib | J9: Key Account | K9: Home & Kitchen | L9: Blender | M9: 87.17 | N9: 1 | O9: 0.1341 | P9: 52.93 | Q9: =M9*N9*(1-O9) -> 75.480503 | R9: =M9*N9*O9 -> 11.689497 | S9: =P9*N9 -> 52.93 | T9: =Q9-S9 -> 22.550503 | U9: =IFERROR(T9/Q9,0) -> 0.29875931 | V9: Yes | W9: Bank Transfer
A10: ORD-00009 | B10: 45294 | C10: =YEAR(B10) -> 2024 | D10: ="Q"&ROUNDUP(MONTH(B10)/3,0) -> Q1 | E10: North | F10: Wholesale | G10: Mona Hassan | H10: CUST-0084 | I10: Heba Soliman | J10: New / Occasional | K10: Office Supplies | L10: LED Desk Lamp | M10: 66.56 | N10: 48 | O10: 0.019 | P10: 34.37 | Q10: =M10*N10*(1-O10) -> 3134.1773 | R10: =M10*N10*O10 -> 60.70272 | S10: =P10*N10 -> 1649.76 | T10: =Q10-S10 -> 1484.4173 | U10: =IFERROR(T10/Q10,0) -> 0.47362263 | V10: No | W10: Bank Transfer
A11: ORD-00010 | B11: 45294 | C11: =YEAR(B11) -> 2024 | D11: ="Q"&ROUNDUP(MONTH(B11)/3,0) -> Q1 | E11: North | F11: Online | G11: Mona Hassan | H11: CUST-0027 | I11: Hassan El-Sayed | J11: Standard | K11: Apparel | L11: Winter Jacket | M11: 107.59 | N11: 3 | O11: 0.0883 | P11: 44.66 | Q11: =M11*N11*(1-O11) -> 294.26941 | R11: =M11*N11*O11 -> 28.500591 | S11: =P11*N11 -> 133.98 | T11: =Q11-S11 -> 160.28941 | U11: =IFERROR(T11/Q11,0) -> 0.54470293 | V11: No | W11: Credit Card
A12: ORD-00011 | B12: 45294 | C12: =YEAR(B12) -> 2024 | D12: ="Q"&ROUNDUP(MONTH(B12)/3,0) -> Q1 | E12: West | F12: Online | G12: Nourhan Aly | H12: CUST-0003 | I12: Nour Kamel | J12: Key Account | K12: Apparel | L12: Leather Belt | M12: 30.99 | N12: 12 | O12: 0.0493 | P12: 11.43 | Q12: =M12*N12*(1-O12) -> 353.54632 | R12: =M12*N12*O12 -> 18.333684 | S12: =P12*N12 -> 137.16 | T12: =Q12-S12 -> 216.38632 | U12: =IFERROR(T12/Q12,0) -> 0.61204517 | V12: No | W12: PayPal
A13: ORD-00012 | B13: 45294 | C13: =YEAR(B13) -> 2024 | D13: ="Q"&ROUNDUP(MONTH(B13)/3,0) -> Q1 | E13: East | F13: Retail | G13: Yara Mostafa | H13: CUST-0024 | I13: Reem Rashed | J13: Standard | K13: Office Supplies | L13: LED Desk Lamp | M13: 161.13 | N13: 4 | O13: 0.0338 | P13: 75.64 | Q13: =M13*N13*(1-O13) -> 622.73522 | R13: =M13*N13*O13 -> 21.784776 | S13: =P13*N13 -> 302.56 | T13: =Q13-S13 -> 320.17522 | U13: =IFERROR(T13/Q13,0) -> 0.51414343 | V13: No | W13: Credit Card
... A240: ORD-00239 | B240: 45340 | C240: =YEAR(B240) -> 2024 | D240: ="Q"&ROUNDUP(MONTH(B240)/3,0) -> Q1 | E240: Central | F240: Online | G240: Dina Magdy | H240: CUST-0050 | I240: Wael Farouk | J240: Standard | K240: Electronics | L240: Noise-Cancel Headphones | M240: 55.06 | N240: 4 | O240: 0.1118 | P240: 35.96 | Q240: =M240*N240*(1-O240) -> 195.61717 | R240: =M240*N240*O240 -> 24.622832 | S240: =P240*N240 -> 143.84 | T240: =Q240-S240 -> 51.777168 | U240: =IFERROR(T240/Q240,0) -> 0.26468622 | V240: No | W240: Credit Card
A241: ORD-00240 | B241: 45340 | C241: =YEAR(B241) -> 2024 | D241: ="Q"&ROUNDUP(MONTH(B241)/3,0) -> Q1 | E241: North | F241: Online | G241: Tarek Aboul | H241: CUST-0073 | I241: Dalia Ibrahim | J241: New / Occasional | K241: Electronics | L241: Wireless Mouse | M241: 51.44 | N241: 1 | P241: 32 | Q241: =M241*N241*(1-O241) -> 51.44 | R241: =M241*N241*O241 -> 0 | S241: =P241*N241 -> 32 | T241: =Q241-S241 -> 19.44 | U241: =IFERROR(T241/Q241,0) -> 0.37791602 | V241: No | W241: PayPal
A242: ORD-00241 | B242: 45340 | C242: =YEAR(B242) -> 2024 | D242: ="Q"&ROUNDUP(MONTH(B242)/3,0) -> Q1 | E242: South | F242: Retail | G242: Sara Adel | H242: CUST-0003 | I242: Nour Kamel | J242: Key Account | K242: Sporting Goods | L242: Adjustable Dumbbells | M242: 73.75 | N242: 1 | O242: 0.0632 | P242: 36.35 | Q242: =M242*N242*(1-O242) -> 69.089 | R242: =M242*N242*O242 -> 4.661 | S242: =P242*N242 -> 36.35 | T242: =Q242-S242 -> 32.739 | U242: =IFERROR(T242/Q242,0) -> 0.47386704 | V242: Yes | W242: Cash on Delivery
A243: ORD-00242 | B243: 45340 | C243: =YEAR(B243) -> 2024 | D243: ="Q"&ROUNDUP(MONTH(B243)/3,0) -> Q1 | E243: North | F243: Retail | G243: Tarek Aboul | H243: CUST-0005 | I243: Wael Farouk | J243: Key Account | K243: Sporting Goods | L243: Camping Tent | M243: 248.65 | N243: 8 | O243: 0.0571 | P243: 137.9 | Q243: =M243*N243*(1-O243) -> 1875.6167 | R243: =M243*N243*O243 -> 113.58332 | S243: =P243*N243 -> 1103.2 | T243: =Q243-S243 -> 772.41668 | U243: =IFERROR(T243/Q243,0) -> 0.41182012 | V243: No | W243: PayPal
A244: ORD-00243 | B244: 45340 | C244: =YEAR(B244) -> 2024 | D244: ="Q"&ROUNDUP(MONTH(B244)/3,0) -> Q1 | E244: North | F244: Retail | G244: Tarek Aboul | H244: CUST-0043 | I244: Sami Mansour | J244: Standard | K244: Sporting Goods | L244: Bicycle Helmet | M244: 113.91 | N244: 1 | O244: 0.0913 | P244: 63.7 | Q244: =M244*N244*(1-O244) -> 103.51002 | R244: =M244*N244*O244 -> 10.399983 | S244: =P244*N244 -> 63.7 | T244: =Q244-S244 -> 39.810017 | U244: =IFERROR(T244/Q244,0) -> 0.38460062 | V244: No | W244: Credit Card
A245: ORD-00244 | B245: 45340 | C245: =YEAR(B245) -> 2024 | D245: ="Q"&ROUNDUP(MONTH(B245)/3,0) -> Q1 | E245: South | F245: Online | G245: Khaled Fathy | H245: CUST-0061 | I245: Reem Ibrahim | J245: New / Occasional | K245: Sporting Goods | L245: Resistance Bands | M245: 104.21 | N245: 2 | O245: 0.1091 | P245: 59.86 | Q245: =M245*N245*(1-O245) -> 185.68138 | R245: =M245*N245*O245 -> 22.738622 | S245: =P245*N245 -> 119.72 | T245: =Q245-S245 -> 65.961378 | U245: =IFERROR(T245/Q245,0) -> 0.3552396 | V245: No | W245: PayPal
A246: ORD-00245 | B246: 45341 | C246: =YEAR(B246) -> 2024 | D246: ="Q"&ROUNDUP(MONTH(B246)/3,0) -> Q1 | E246: North | F246: Online | G246: Mona Hassan | H246: CUST-0017 | I246: Layla Mansour | J246: Standard | K246: Sporting Goods | L246: Adjustable Dumbbells | M246: 69.19 | N246: 5 | O246: 0.1083 | P246: 33.48 | Q246: =M246*N246*(1-O246) -> 308.48361 | R246: =M246*N246*O246 -> 37.466385 | S246: =P246*N246 -> 167.4 | T246: =Q246-S246 -> 141.08362 | U246: =IFERROR(T246/Q246,0) -> 0.45734557 | V246: No | W246: Cash on Delivery
A247: ORD-00246 | B247: 45341 | C247: =YEAR(B247) -> 2024 | D247: ="Q"&ROUNDUP(MONTH(B247)/3,0) -> Q1 | E247: South | F247: Online | G247: Khaled Fathy | H247: CUST-0008 | I247: Nour Ibrahim | J247: Key Account | K247: Office Supplies | L247: Printer Paper (Case) | M247: 123.92 | N247: 1 | O247: 0.1053 | P247: 63.32 | Q247: =M247*N247*(1-O247) -> 110.87122 | R247: =M247*N247*O247 -> 13.048776 | S247: =P247*N247 -> 63.32 | T247: =Q247-S247 -> 47.551224 | U247: =IFERROR(T247/Q247,0) -> 0.42888698 | V247: No | W247: Credit Card
A248: ORD-00247 | B248: 45341 | C248: =YEAR(B248) -> 2024 | D248: ="Q"&ROUNDUP(MONTH(B248)/3,0) -> Q1 | E248: North | F248: Wholesale | G248: Tarek Aboul | H248: CUST-0144 | I248: Adel El-Masry | J248: New / Occasional | K248: Apparel | L248: Winter Jacket | M248: 37.11 | N248: 5 | O248: 0 | P248: 14.27 | Q248: =M248*N248*(1-O248) -> 185.55 | R248: =M248*N248*O248 -> 0 | S248: =P248*N248 -> 71.35 | T248: =Q248-S248 -> 114.2 | U248: =IFERROR(T248/Q248,0) -> 0.61546753 | V248: No | W248: Cash on Delivery
A249: ORD-00248 | B249: 45341 | C249: =YEAR(B249) -> 2024 | D249: ="Q"&ROUNDUP(MONTH(B249)/3,0) -> Q1 | E249: North | F249: Online | G249: Tarek Aboul | H249: CUST-0131 | I249: Fady Abdallah | J249: New / Occasional | K249: Office Supplies | L249: Ergonomic Chair | M249: 48.95 | N249: 2 | O249: 0.153 | P249: 25.09 | Q249: =M249*N249*(1-O249) -> 82.9213 | R249: =M249*N249*O249 -> 14.9787 | S249: =P249*N249 -> 50.18 | T249: =Q249-S249 -> 32.7413 | U249: =IFERROR(T249/Q249,0) -> 0.39484789 | V249: No | W249: Credit Card
A250: ORD-00249 | B250: 45341 | C250: =YEAR(B250) -> 2024 | D250: ="Q"&ROUNDUP(MONTH(B250)/3,0) -> Q1 | E250: East | F250: Online | G250: Yara Mostafa | H250: CUST-0008 | I250: Nour Ibrahim | J250: Key Account | K250: Home & Kitchen | L250: Vacuum Cleaner | M250: 83.64 | N250: 1 | O250: 0.1128 | P250: 49.94 | Q250: =M250*N250*(1-O250) -> 74.205408 | R250: =M250*N250*O250 -> 9.434592 | S250: =P250*N250 -> 49.94 | T250: =Q250-S250 -> 24.265408 | U250: =IFERROR(T250/Q250,0) -> 0.32700323 | V250: No | W250: Credit Card
A251: ORD-00250 | B251: 45341 | C251: =YEAR(B251) -> 2024 | D251: ="Q"&ROUNDUP(MONTH(B251)/3,0) -> Q1 | E251: South | F251: Online | G251: Sara Adel | H251: CUST-0041 | I251: Nour El-Sayed | J251: Standard | K251: Apparel | L251: Denim Jeans | M251: 70.16 | N251: 2 | O251: 0.1393 | P251: 31.31 | Q251: =M251*N251*(1-O251) -> 120.77342 | R251: =M251*N251*O251 -> 19.546576 | S251: =P251*N251 -> 62.62 | T251: =Q251-S251 -> 58.153424 | U251: =IFERROR(T251/Q251,0) -> 0.48150845 | V251: No | W251: Bank Transfer
A252: ORD-00251 | B252: 45341 | C252: =YEAR(B252) -> 2024 | D252: ="Q"&ROUNDUP(MONTH(B252)/3,0) -> Q1 | E252: North | F252: Online | G252: Mona Hassan | H252: CUST-0079 | I252: Hassan Kamel | J252: New / Occasional | K252: Home & Kitchen | L252: Vacuum Cleaner | M252: 191.23 | N252: 1 | O252: 0.0637 | P252: 116.2 | Q252: =M252*N252*(1-O252) -> 179.04865 | R252: =M252*N252*O252 -> 12.181351 | S252: =P252*N252 -> 116.2 | T252: =Q252-S252 -> 62.848649 | U252: =IFERROR(T252/Q252,0) -> 0.35101437 | V252: No | W252: PayPal
A253: ORD-00252 | B253: 45341 | C253: =YEAR(B253) -> 2024 | D253: ="Q"&ROUNDUP(MONTH(B253)/3,0) -> Q1 | E253: North | F253: Retail | G253: Tarek Aboul | H253: CUST-0007 | I253: Hassan Naguib | J253: Key Account | K253: Office Supplies | L253: LED Desk Lamp | M253: 241.31 | N253: 1 | O253: 0.0411 | P253: 126.15 | Q253: =M253*N253*(1-O253) -> 231.39216 | R253: =M253*N253*O253 -> 9.917841 | S253: =P253*N253 -> 126.15 | T253: =Q253-S253 -> 105.24216 | U253: =IFERROR(T253/Q253,0) -> 0.45482163 | V253: No | W253: Bank Transfer
... A300: ORD-00299 | B300: 45351 | C300: =YEAR(B300) -> 2024 | D300: ="Q"&ROUNDUP(MONTH(B300)/3,0) -> Q1 | E300: South | F300: Online | G300: Khaled Fathy | H300: CUST-0035 | I300: Hassan Abdallah | J300: Standard | K300: Electronics | L300: Noise-Cancel Headphones | M300: 303.02 | N300: 2 | O300: 0.063 | P300: 173.16 | Q300: =M300*N300*(1-O300) -> 567.85948 | R300: =M300*N300*O300 -> 38.18052 | S300: =P300*N300 -> 346.32 | T300: =Q300-S300 -> 221.53948 | U300: =IFERROR(T300/Q300,0) -> 0.39013081 | V300: No | W300: Bank Transfer
A301: ORD-00300 | B301: 45351 | C301: =YEAR(B301) -> 2024 | D301: ="Q"&ROUNDUP(MONTH(B301)/3,0) -> Q1 | E301: North | F301: Online | G301: Mona Hassan | H301: CUST-0102 | I301: Layla Fahmy | J301: New / Occasional | K301: Electronics | L301: Noise-Cancel Headphones | M301: 257.45 | N301: 8 | P301: 147.83 | Q301: =M301*N301*(1-O301) -> 2059.6 | R301: =M301*N301*O301 -> 0 | S301: =P301*N301 -> 1182.64 | T301: =Q301-S301 -> 876.96 | U301: =IFERROR(T301/Q301,0) -> 0.42579142 | V301: No | W301: PayPal
A302: ORD-00301 | B302: 45351 | C302: =YEAR(B302) -> 2024 | D302: ="Q"&ROUNDUP(MONTH(B302)/3,0) -> Q1 | E302: South | F302: Retail | G302: Khaled Fathy | H302: CUST-0003 | I302: Nour Kamel | J302: Key Account | K302: Home & Kitchen | L302: Blender | M302: 38.67 | N302: 1 | O302: 0.0315 | P302: 21.01 | Q302: =M302*N302*(1-O302) -> 37.451895 | R302: =M302*N302*O302 -> 1.218105 | S302: =P302*N302 -> 21.01 | T302: =Q302-S302 -> 16.441895 | U302: =IFERROR(T302/Q302,0) -> 0.4390137 | V302: Yes | W302: Bank Transfer
A303: ORD-00302 | B303: 45352 | C303: =YEAR(B303) -> 2024 | D303: ="Q"&ROUNDUP(MONTH(B303)/3,0) -> Q1 | E303: South | F303: Online | G303: Sara Adel | H303: CUST-0018 | I303: Tamer Fahmy | J303: Standard | K303: Electronics | L303: Noise-Cancel Headphones | M303: 156.07 | N303: 4 | O303: 0.173 | P303: 88.35 | Q303: =M303*N303*(1-O303) -> 516.27956 | R303: =M303*N303*O303 -> 108.00044 | S303: =P303*N303 -> 353.4 | T303: =Q303-S303 -> 162.87956 | U303: =IFERROR(T303/Q303,0) -> 0.31548714 | V303: No | W303: Bank Transfer
A304: ORD-00303 | B304: 45352 | C304: =YEAR(B304) -> 2024 | D304: ="Q"&ROUNDUP(MONTH(B304)/3,0) -> Q1 | E304: East | F304: Retail | G304: Yara Mostafa | H304: CUST-0042 | I304: Youssef Soliman | J304: Standard | K304: Home & Kitchen | L304: Cookware Set | M304: 205.17 | N304: 3 | O304: 0.108 | P304: 113.3 | Q304: =M304*N304*(1-O304) -> 549.03492 | R304: =M304*N304*O304 -> 66.47508 | S304: =P304*N304 -> 339.9 | T304: =Q304-S304 -> 209.13492 | U304: =IFERROR(T304/Q304,0) -> 0.38091369 | V304: No | W304: Bank Transfer
A305: ORD-00304 | B305: 45352 | C305: =YEAR(B305) -> 2024 | D305: ="Q"&ROUNDUP(MONTH(B305)/3,0) -> Q1 | E305: Central | F305: Wholesale | G305: Ahmed Reda | H305: CUST-0075 | I305: Heba Sherif | J305: New / Occasional | K305: Sporting Goods | L305: Yoga Mat | M305: 175.62 | N305: 5 | O305: 0.0318 | P305: 85.19 | Q305: =M305*N305*(1-O305) -> 850.17642 | R305: =M305*N305*O305 -> 27.92358 | S305: =P305*N305 -> 425.95 | T305: =Q305-S305 -> 424.22642 | U305: =IFERROR(T305/Q305,0) -> 0.49898634 | V305: No | W305: Cash on Delivery
A306: ORD-00305 | B306: 45352 | C306: =YEAR(B306) -> 2024 | D306: ="Q"&ROUNDUP(MONTH(B306)/3,0) -> Q1 | E306: North | F306: Retail | G306: Tarek Aboul | H306: CUST-0003 | I306: Nour Kamel | J306: Key Account | K306: Apparel | L306: Denim Jeans | M306: 47.88 | N306: 2 | O306: 0.0408 | P306: 20.29 | Q306: =M306*N306*(1-O306) -> 91.852992 | R306: =M306*N306*O306 -> 3.907008 | S306: =P306*N306 -> 40.58 | T306: =Q306-S306 -> 51.272992 | U306: =IFERROR(T306/Q306,0) -> 0.5582071 | V306: No | W306: Credit Card
A307: ORD-00306 | B307: 45352 | C307: =YEAR(B307) -> 2024 | D307: ="Q"&ROUNDUP(MONTH(B307)/3,0) -> Q1 | E307: West | F307: Retail | G307: Nourhan Aly | H307: CUST-0009 | I307: Reem Naguib | J307: Key Account | K307: Electronics | L307: Smart Watch | M307: 108.93 | N307: 1 | O307: 0.091 | P307: 71.66 | Q307: =M307*N307*(1-O307) -> 99.01737 | R307: =M307*N307*O307 -> 9.91263 | S307: =P307*N307 -> 71.66 | T307: =Q307-S307 -> 27.35737 | U307: =IFERROR(T307/Q307,0) -> 0.27628859 | V307: No | W307: PayPal
A308: ORD-00307 | B308: 45352 | C308: =YEAR(B308) -> 2024 | D308: ="Q"&ROUNDUP(MONTH(B308)/3,0) -> Q1 | E308: East | F308: Retail | G308: Yara Mostafa | H308: CUST-0041 | I308: Nour El-Sayed | J308: Standard | K308: Apparel | L308: Leather Belt | M308: 78.96 | N308: 2 | O308: 0.0505 | P308: 35.93 | Q308: =M308*N308*(1-O308) -> 149.94504 | R308: =M308*N308*O308 -> 7.97496 | S308: =P308*N308 -> 71.86 | T308: =Q308-S308 -> 78.08504 | U308: =IFERROR(T308/Q308,0) -> 0.52075774 | V308: No | W308: Bank Transfer
A309: ORD-00308 | B309: 45352 | C309: =YEAR(B309) -> 2024 | D309: ="Q"&ROUNDUP(MONTH(B309)/3,0) -> Q1 | E309: North | F309: Wholesale | G309: Tarek Aboul | H309: CUST-0086 | I309: Fady Aziz | J309: New / Occasional | K309: Home & Kitchen | L309: Blender | M309: 101.77 | N309: 8 | O309: 0.0178 | P309: 52.19 | Q309: =M309*N309*(1-O309) -> 799.66795 | R309: =M309*N309*O309 -> 14.492048 | S309: =P309*N309 -> 417.52 | T309: =Q309-S309 -> 382.14795 | U309: =IFERROR(T309/Q309,0) -> 0.47788329 | V309: No | W309: PayPal
A310: ORD-00309 | B310: 45353 | C310: =YEAR(B310) -> 2024 | D310: ="Q"&ROUNDUP(MONTH(B310)/3,0) -> Q1 | E310: East | F310: Online | G310: Yara Mostafa | H310: CUST-0172 | I310: Omar El-Sayed | J310: New / Occasional | K310: Electronics | L310: Wireless Mouse | M310: 222.1 | N310: 1 | O310: 0.0651 | P310: 145.49 | Q310: =M310*N310*(1-O310) -> 207.64129 | R310: =M310*N310*O310 -> 14.45871 | S310: =P310*N310 -> 145.49 | T310: =Q310-S310 -> 62.15129 | U310: =IFERROR(T310/Q310,0) -> 0.29932048 | V310: No | W310: Bank Transfer
A311: ORD-00310 | B311: 45353 | C311: =YEAR(B311) -> 2024 | D311: ="Q"&ROUNDUP(MONTH(B311)/3,0) -> Q1 | E311: West | F311: Online | G311: Nourhan Aly | H311: CUST-0002 | I311: Sami Sherif | J311: Key Account | K311: Home & Kitchen | L311: Air Fryer | M311: 76.42 | N311: 1 | O311: 0.0785 | P311: 39.36 | Q311: =M311*N311*(1-O311) -> 70.42103 | R311: =M311*N311*O311 -> 5.99897 | S311: =P311*N311 -> 39.36 | T311: =Q311-S311 -> 31.06103 | U311: =IFERROR(T311/Q311,0) -> 0.44107605 | V311: No | W311: Credit Card
A312: ORD-00311 | B312: 45354 | C312: =YEAR(B312) -> 2024 | D312: ="Q"&ROUNDUP(MONTH(B312)/3,0) -> Q1 | E312: North | F312: Wholesale | G312: Mona Hassan | H312: CUST-0042 | I312: Youssef Soliman | J312: Standard | K312: Sporting Goods | L312: Bicycle Helmet | M312: 43.05 | N312: 5 | O312: 0.0389 | P312: 19.47 | Q312: =M312*N312*(1-O312) -> 206.87677 | R312: =M312*N312*O312 -> 8.373225 | S312: =P312*N312 -> 97.35 | T312: =Q312-S312 -> 109.52677 | U312: =IFERROR(T312/Q312,0) -> 0.52943002 | V312: No | W312: Cash on Delivery
...

Sheet Analysis_Data
A1: Company Totals
A2: Total Revenue | B2: =SUM(Sales_Transactions!$Q$2:$Q$4411) -> 1945626.1
A3: Total Net Profit | B3: =SUM(Sales_Transactions!$T$2:$T$4411) -> 744281.38
A4: Overall Margin % | B4: =B3/B2 -> 0.38254081
A5: Total Orders | B5: =COUNTA(Sales_Transactions!$H$2:$H$4411) -> 4410
A6: Company Return Rate | B6: =COUNTIF(Sales_Transactions!$V$2:$V$4411,"Yes")/B5 -> 0.079591837
A9: Problem 1 — Customer Revenue Concentration (Top 20 of 180 Customers)
A10: Rank | B10: Customer_ID | C10: Customer_Name | D10: Segment | E10: Revenue | F10: Cumulative Revenue | G10: Cumulative %
A11: 1 | B11: CUST-0002 | C11: Sami Sherif | D11: Key Account | E11: =SUMIF(Sales_Transactions!$H$2:$H$4411,B11,Sales_Transactions!$Q$2:$Q$4411) -> 94608.859 | F11: =E11 -> 94608.859 | G11: =F11/$B$2 -> 0.048626435
A12: 2 | B12: CUST-0003 | C12: Nour Kamel | D12: Key Account | E12: =SUMIF(Sales_Transactions!$H$2:$H$4411,B12,Sales_Transactions!$Q$2:$Q$4411) -> 90463.351 | F12: =F11+E12 -> 185072.21 | G12: =F12/$B$2 -> 0.095122188
A13: 3 | B13: CUST-0004 | C13: Layla Mansour | D13: Key Account | E13: =SUMIF(Sales_Transactions!$H$2:$H$4411,B13,Sales_Transactions!$Q$2:$Q$4411) -> 86586.325 | F13: =F12+E13 -> 271658.54 | G13: =F13/$B$2 -> 0.13962525
A14: 4 | B14: CUST-0005 | C14: Wael Farouk | D14: Key Account | E14: =SUMIF(Sales_Transactions!$H$2:$H$4411,B14,Sales_Transactions!$Q$2:$Q$4411) -> 78959.784 | F14: =F13+E14 -> 350618.32 | G14: =F14/$B$2 -> 0.18020848
A15: 5 | B15: CUST-0001 | C15: Layla Ibrahim | D15: Key Account | E15: =SUMIF(Sales_Transactions!$H$2:$H$4411,B15,Sales_Transactions!$Q$2:$Q$4411) -> 76555.401 | F15: =F14+E15 -> 427173.72 | G15: =F15/$B$2 -> 0.21955592
A16: 6 | B16: CUST-0006 | C16: Mona Ibrahim | D16: Key Account | E16: =SUMIF(Sales_Transactions!$H$2:$H$4411,B16,Sales_Transactions!$Q$2:$Q$4411) -> 52236.529 | F16: =F15+E16 -> 479410.25 | G16: =F16/$B$2 -> 0.2464041
A17: 7 | B17: CUST-0007 | C17: Hassan Naguib | D17: Key Account | E17: =SUMIF(Sales_Transactions!$H$2:$H$4411,B17,Sales_Transactions!$Q$2:$Q$4411) -> 50640.551 | F17: =F16+E17 -> 530050.8 | G17: =F17/$B$2 -> 0.272432
A18: 8 | B18: CUST-0009 | C18: Reem Naguib | D18: Key Account | E18: =SUMIF(Sales_Transactions!$H$2:$H$4411,B18,Sales_Transactions!$Q$2:$Q$4411) -> 50384.048 | F18: =F17+E18 -> 580434.85 | G18: =F18/$B$2 -> 0.29832806
A19: 9 | B19: CUST-0008 | C19: Nour Ibrahim | D19: Key Account | E19: =SUMIF(Sales_Transactions!$H$2:$H$4411,B19,Sales_Transactions!$Q$2:$Q$4411) -> 38400.601 | F19: =F18+E19 -> 618835.45 | G19: =F19/$B$2 -> 0.31806494
A20: 10 | B20: CUST-0010 | C20: Reem Farouk | D20: Key Account | E20: =SUMIF(Sales_Transactions!$H$2:$H$4411,B20,Sales_Transactions!$Q$2:$Q$4411) -> 34718.372 | F20: =F19+E20 -> 653553.82 | G20: =F20/$B$2 -> 0.33590926
A21: 11 | B21: CUST-0016 | C21: Karim El-Masry | D21: Standard | E21: =SUMIF(Sales_Transactions!$H$2:$H$4411,B21,Sales_Transactions!$Q$2:$Q$4411) -> 33521.242 | F21: =F20+E21 -> 687075.06 | G21: =F21/$B$2 -> 0.35313829
A22: 12 | B22: CUST-0019 | C22: Salma Hamdy | D22: Standard | E22: =SUMIF(Sales_Transactions!$H$2:$H$4411,B22,Sales_Transactions!$Q$2:$Q$4411) -> 29934.677 | F22: =F21+E22 -> 717009.74 | G22: =F22/$B$2 -> 0.36852392
A23: 13 | B23: CUST-0013 | C23: Ali Abdallah | D23: Standard | E23: =SUMIF(Sales_Transactions!$H$2:$H$4411,B23,Sales_Transactions!$Q$2:$Q$4411) -> 29165.326 | F23: =F22+E23 -> 746175.07 | G23: =F23/$B$2 -> 0.38351412
... A30: 20 | B30: CUST-0041 | C30: Nour El-Sayed | D30: Standard | E30: =SUMIF(Sales_Transactions!$H$2:$H$4411,B30,Sales_Transactions!$Q$2:$Q$4411) -> 24345.432 | F30: =F29+E30 -> 926708.6 | G30: =F30/$B$2 -> 0.47630355
B31: OTHER | C31: All Other Customers (160) | D31: Mixed | E31: =$B$2-F30 -> 1018917.5 | F31: =$B$2 -> 1945626.1 | G31: 1
A34: Problem 2 — Monthly Discount & Margin Trend
A35: Month | B35: Revenue | C35: Discount Amount | D35: Net Profit | E35: Avg Discount % | F35: Margin %
A36: 45292 | B36: =SUMIFS(Sales_Transactions!$Q$2:$Q$4411,Sales_Transactions!$B$2:$B$4411,">="&A36,Sales_Transactions!$B$2:$B$4411,"<"&EDATE(A36,1)) -> 86466.817 | C36: =SUMIFS(Sales_Transactions!$R$2:$R$4411,Sales_Transactions!$B$2:$B$4411,">="&A36,Sales_Transactions!$B$2:$B$4411,"<"&EDATE(A36,1)) -> 4891.1532 | D36: =SUMIFS(Sales_Transactions!$T$2:$T$4411,Sales_Transactions!$B$2:$B$4411,">="&A36,Sales_Transactions!$B$2:$B$4411,"<"&EDATE(A36,1)) -> 37713.057 | E36: =C36/(B36+C36) -> 0.05353833 | F36: =IFERROR(D36/B36,0) -> 0.43615641
A37: =EDATE(A36,1) -> 45323 | B37: =SUMIFS(Sales_Transactions!$Q$2:$Q$4411,Sales_Transactions!$B$2:$B$4411,">="&A37,Sales_Transactions!$B$2:$B$4411,"<"&EDATE(A37,1)) -> 60468.182 | C37: =SUMIFS(Sales_Transactions!$R$2:$R$4411,Sales_Transactions!$B$2:$B$4411,">="&A37,Sales_Transactions!$B$2:$B$4411,"<"&EDATE(A37,1)) -> 5232.8884 | D37: =SUMIFS(Sales_Transactions!$T$2:$T$4411,Sales_Transactions!$B$2:$B$4411,">="&A37,Sales_Transactions!$B$2:$B$4411,"<"&EDATE(A37,1)) -> 24836.102 | E37: =C37/(B37+C37) -> 0.079646928 | F37: =IFERROR(D37/B37,0) -> 0.41073009
A38: =EDATE(A37,1) -> 45352 | B38: =SUMIFS(Sales_Transactions!$Q$2:$Q$4411,Sales_Transactions!$B$2:$B$4411,">="&A38,Sales_Transactions!$B$2:$B$4411,"<"&EDATE(A38,1)) -> 74031.7 | C38: =SUMIFS(Sales_Transactions!$R$2:$R$4411,Sales_Transactions!$B$2:$B$4411,">="&A38,Sales_Transactions!$B$2:$B$4411,"<"&EDATE(A38,1)) -> 6370.6105 | D38: =SUMIFS(Sales_Transactions!$T$2:$T$4411,Sales_Transactions!$B$2:$B$4411,">="&A38,Sales_Transactions!$B$2:$B$4411,"<"&EDATE(A38,1)) -> 31142.15 | E38: =C38/(B38+C38) -> 0.079234172 | F38: =IFERROR(D38/B38,0) -> 0.42065966
A39: =EDATE(A38,1) -> 45383 | B39: =SUMIFS(Sales_Transactions!$Q$2:$Q$4411,Sales_Transactions!$B$2:$B$4411,">="&A39,Sales_Transactions!$B$2:$B$4411,"<"&EDATE(A39,1)) -> 94800.131 | C39: =SUMIFS(Sales_Transactions!$R$2:$R$4411,Sales_Transactions!$B$2:$B$4411,">="&A39,Sales_Transactions!$B$2:$B$4411,"<"&EDATE(A39,1)) -> 6807.919 | D39: =SUMIFS(Sales_Transactions!$T$2:$T$4411,Sales_Transactions!$B$2:$B$4411,">="&A39,Sales_Transactions!$B$2:$B$4411,"<"&EDATE(A39,1)) -> 40112.431 | E39: =C39/(B39+C39) -> 0.067001768 | F39: =IFERROR(D39/B39,0) -> 0.42312632
A40: =EDATE(A39,1) -> 45413 | B40: =SUMIFS(Sales_Transactions!$Q$2:$Q$4411,Sales_Transactions!$B$2:$B$4411,">="&A40,Sales_Transactions!$B$2:$B$4411,"<"&EDATE(A40,1)) -> 62752.658 | C40: =SUMIFS(Sales_Transactions!$R$2:$R$4411,Sales_Transactions!$B$2:$B$4411,">="&A40,Sales_Transactions!$B$2:$B$4411,"<"&EDATE(A40,1)) -> 5358.4724 | D40: =SUMIFS(Sales_Transactions!$T$2:$T$4411,Sales_Transactions!$B$2:$B$4411,">="&A40,Sales_Transactions!$B$2:$B$4411,"<"&EDATE(A40,1)) -> 25418.158 | E40: =C40/(B40+C40) -> 0.078672493 | F40: =IFERROR(D40/B40,0) -> 0.40505309
A41: =EDATE(A40,1) -> 45444 | B41: =SUMIFS(Sales_Transactions!$Q$2:$Q$4411,Sales_Transactions!$B$2:$B$4411,">="&A41,Sales_Transactions!$B$2:$B$4411,"<"&EDATE(A41,1)) -> 75030.305 | C41: =SUMIFS(Sales_Transactions!$R$2:$R$4411,Sales_Transactions!$B$2:$B$4411,">="&A41,Sales_Transactions!$B$2:$B$4411,"<"&EDATE(A41,1)) -> 8497.2354 | D41: =SUMIFS(Sales_Transactions!$T$2:$T$4411,Sales_Transactions!$B$2:$B$4411,">="&A41,Sales_Transactions!$B$2:$B$4411,"<"&EDATE(A41,1)) -> 30145.795 | E41: =C41/(B41+C41) -> 0.10172975 | F41: =IFERROR(D41/B41,0) -> 0.40178158
A42: =EDATE(A41,1) -> 45474 | B42: =SUMIFS(Sales_Transactions!$Q$2:$Q$4411,Sales_Transactions!$B$2:$B$4411,">="&A42,Sales_Transactions!$B$2:$B$4411,"<"&EDATE(A42,1)) -> 63619.357 | C42: =SUMIFS(Sales_Transactions!$R$2:$R$4411,Sales_Transactions!$B$2:$B$4411,">="&A42,Sales_Transactions!$B$2:$B$4411,"<"&EDATE(A42,1)) -> 7188.3033 | D42: =SUMIFS(Sales_Transactions!$T$2:$T$4411,Sales_Transactions!$B$2:$B$4411,">="&A42,Sales_Transactions!$B$2:$B$4411,"<"&EDATE(A42,1)) -> 25231.877 | E42: =C42/(B42+C42) -> 0.10151872 | F42: =IFERROR(D42/B42,0) -> 0.39660691
A43: =EDATE(A42,1) -> 45505 | B43: =SUMIFS(Sales_Transactions!$Q$2:$Q$4411,Sales_Transactions!$B$2:$B$4411,">="&A43,Sales_Transactions!$B$2:$B$4411,"<"&EDATE(A43,1)) -> 74740.35 | C43: =SUMIFS(Sales_Transactions!$R$2:$R$4411,Sales_Transactions!$B$2:$B$4411,">="&A43,Sales_Transactions!$B$2:$B$4411,"<"&EDATE(A43,1)) -> 9449.56 | D43: =SUMIFS(Sales_Transactions!$T$2:$T$4411,Sales_Transactions!$B$2:$B$4411,">="&A43,Sales_Transactions!$B$2:$B$4411,"<"&EDATE(A43,1)) -> 29307.34 | E43: =C43/(B43+C43) -> 0.112241 | F43: =IFERROR(D43/B43,0) -> 0.39212206
A44: =EDATE(A43,1) -> 45536 | B44: =SUMIFS(Sales_Transactions!$Q$2:$Q$4411,Sales_Transactions!$B$2:$B$4411,">="&A44,Sales_Transactions!$B$2:$B$4411,"<"&EDATE(A44,1)) -> 62334.823 | C44: =SUMIFS(Sales_Transactions!$R$2:$R$4411,Sales_Transactions!$B$2:$B$4411,">="&A44,Sales_Transactions!$B$2:$B$4411,"<"&EDATE(A44,1)) -> 8194.0966 | D44: =SUMIFS(Sales_Transactions!$T$2:$T$4411,Sales_Transactions!$B$2:$B$4411,">="&A44,Sales_Transactions!$B$2:$B$4411,"<"&EDATE(A44,1)) -> 25746.663 | E44: =C44/(B44+C44) -> 0.11618066 | F44: =IFERROR(D44/B44,0) -> 0.4130382
A45: =EDATE(A44,1) -> 45566 | B45: =SUMIFS(Sales_Transactions!$Q$2:$Q$4411,Sales_Transactions!$B$2:$B$4411,">="&A45,Sales_Transactions!$B$2:$B$4411,"<"&EDATE(A45,1)) -> 71834.66 | C45: =SUMIFS(Sales_Transactions!$R$2:$R$4411,Sales_Transactions!$B$2:$B$4411,">="&A45,Sales_Transactions!$B$2:$B$4411,"<"&EDATE(A45,1)) -> 9697.8901 | D45: =SUMIFS(Sales_Transactions!$T$2:$T$4411,Sales_Transactions!$B$2:$B$4411,">="&A45,Sales_Transactions!$B$2:$B$4411,"<"&EDATE(A45,1)) -> 27971.43 | E45: =C45/(B45+C45) -> 0.11894501 | F45: =IFERROR(D45/B45,0) -> 0.38938626
A46: =EDATE(A45,1) -> 45597 | B46: =SUMIFS(Sales_Transactions!$Q$2:$Q$4411,Sales_Transactions!$B$2:$B$4411,">="&A46,Sales_Transactions!$B$2:$B$4411,"<"&EDATE(A46,1)) -> 91333.669 | C46: =SUMIFS(Sales_Transactions!$R$2:$R$4411,Sales_Transactions!$B$2:$B$4411,">="&A46,Sales_Transactions!$B$2:$B$4411,"<"&EDATE(A46,1)) -> 15466.271 | D46: =SUMIFS(Sales_Transactions!$T$2:$T$4411,Sales_Transactions!$B$2:$B$4411,">="&A46,Sales_Transactions!$B$2:$B$4411,"<"&EDATE(A46,1)) -> 35644.269 | E46: =C46/(B46+C46) -> 0.14481536 | F46: =IFERROR(D46/B46,0) -> 0.39026428
A47: =EDATE(A46,1) -> 45627 | B47: =SUMIFS(Sales_Transactions!$Q$2:$Q$4411,Sales_Transactions!$B$2:$B$4411,">="&A47,Sales_Transactions!$B$2:$B$4411,"<"&EDATE(A47,1)) -> 114014.76 | C47: =SUMIFS(Sales_Transactions!$R$2:$R$4411,Sales_Transactions!$B$2:$B$4411,">="&A47,Sales_Transactions!$B$2:$B$4411,"<"&EDATE(A47,1)) -> 17504.913 | D47: =SUMIFS(Sales_Transactions!$T$2:$T$4411,Sales_Transactions!$B$2:$B$4411,">="&A47,Sales_Transactions!$B$2:$B$4411,"<"&EDATE(A47,1)) -> 45107.457 | E47: =C47/(B47+C47) -> 0.1330973 | F47: =IFERROR(D47/B47,0) -> 0.39562823
A48: =EDATE(A47,1) -> 45658 | B48: =SUMIFS(Sales_Transactions!$Q$2:$Q$4411,Sales_Transactions!$B$2:$B$4411,">="&A48,Sales_Transactions!$B$2:$B$4411,"<"&EDATE(A48,1)) -> 85492.521 | C48: =SUMIFS(Sales_Transactions!$R$2:$R$4411,Sales_Transactions!$B$2:$B$4411,">="&A48,Sales_Transactions!$B$2:$B$4411,"<"&EDATE(A48,1)) -> 11899.179 | D48: =SUMIFS(Sales_Transactions!$T$2:$T$4411,Sales_Transactions!$B$2:$B$4411,">="&A48,Sales_Transactions!$B$2:$B$4411,"<"&EDATE(A48,1)) -> 34617.821 | E48: =C48/(B48+C48) -> 0.12217857 | F48: =IFERROR(D48/B48,0) -> 0.40492222
... A59: =EDATE(A58,1) -> 45992 | B59: =SUMIFS(Sales_Transactions!$Q$2:$Q$4411,Sales_Transactions!$B$2:$B$4411,">="&A59,Sales_Transactions!$B$2:$B$4411,"<"&EDATE(A59,1)) -> 127567.88 | C59: =SUMIFS(Sales_Transactions!$R$2:$R$4411,Sales_Transactions!$B$2:$B$4411,">="&A59,Sales_Transactions!$B$2:$B$4411,"<"&EDATE(A59,1)) -> 33406.296 | D59: =SUMIFS(Sales_Transactions!$T$2:$T$4411,Sales_Transactions!$B$2:$B$4411,">="&A59,Sales_Transactions!$B$2:$B$4411,"<"&EDATE(A59,1)) -> 43150.704 | E59: =C59/(B59+C59) -> 0.2075258 | F59: =IFERROR(D59/B59,0) -> 0.3382568
A62: Problem 3 — Regional Revenue Trend by Month
...
